Traceback (most recent call last):
  File "manage.py", line 21, in <module>
    main()
  File "manage.py", line 17, in main
    execute_from_command_line(sys.argv)
  File "/root/anaconda3/lib/python3.7/site-packages/django/core/management/__init__.py", line 401, in execute_from_command_line
    utility.execute()
  File "/root/anaconda3/lib/python3.7/site-packages/django/core/management/__init__.py", line 395, in execute
    self.fetch_command(subcommand).run_from_argv(self.argv)
  File "/root/anaconda3/lib/python3.7/site-packages/django/core/management/base.py", line 328, in run_from_argv
    self.execute(*args, **cmd_options)
  File "/root/anaconda3/lib/python3.7/site-packages/django/core/management/base.py", line 369, in execute
    output = self.handle(*args, **options)
  File "/root/anaconda3/lib/python3.7/site-packages/django_extensions/management/utils.py", line 62, in inner
    ret = func(self, *args, **kwargs)
  File "/root/anaconda3/lib/python3.7/site-packages/django_extensions/management/commands/runserver_plus.py", line 218, in handle
    self.inner_run(options)
  File "/root/anaconda3/lib/python3.7/site-packages/django_extensions/management/commands/runserver_plus.py", line 345, in inner_run
    ssl_context=ssl_context,
  File "/root/anaconda3/lib/python3.7/site-packages/werkzeug/serving.py", line 1030, in run_simple
    s.bind(server_address)
OSError: [Errno 98] Address already in use
